“Hello World”
Wed Feb 12 22:16:21 2025       
+-----------------------------------------------------------------------------------------+
| NVIDIA-SMI 550.144.03             Driver Version: 550.144.03     CUDA Version: 12.4     |
|-----------------------------------------+------------------------+----------------------+
| GPU  Name                 Persistence-M | Bus-Id          Disp.A | Volatile Uncorr. ECC |
| Fan  Temp   Perf          Pwr:Usage/Cap |           Memory-Usage | GPU-Util  Compute M. |
|                                         |                        |               MIG M. |
|=========================================+========================+======================|
|   0  NVIDIA A100-SXM4-40GB          Off |   00000000:01:00.0 Off |                    0 |
| N/A   29C    P0             52W /  400W |       1MiB /  40960MiB |      0%      Default |
|                                         |                        |             Disabled |
+-----------------------------------------+------------------------+----------------------+
                                                                                         
+-----------------------------------------------------------------------------------------+
| Processes:                                                                              |
|  GPU   GI   CI        PID   Type   Process name                              GPU Memory |
|        ID   ID                                                               Usage      |
|=========================================================================================|
|  No running processes found                                                             |
+-----------------------------------------------------------------------------------------+
/lustre06/project/6067608/achint/diffusion-forcing-transformer/dfot/lib/python3.10/site-packages/hydra/_internal/defaults_list.py:251: UserWarning: In 'config': Defaults list is missing `_self_`. See https://hydra.cc/docs/1.2/upgrades/1.0_to_1.1/default_composition_order for more information
  warnings.warn(msg, UserWarning)
Error executing job with overrides: ['+name=single_image_to_short', 'dataset=realestate10k_mini', 'algorithm=dfot_video_pose', 'experiment=video_generation', '++algorithm={diffusion: {is_continuous: True, precond_scale: 0.125}, backbone: {use_fourier_noise_embedding: True}}', 'load=pretrained:DFoT_RE10K.ckpt', 'experiment.tasks=[validation]', 'experiment.validation.data.shuffle=True', 'dataset.context_length=1', 'dataset.frame_skip=20', 'dataset.n_frames=8', 'experiment.validation.batch_size=1', 'algorithm.tasks.prediction.history_guidance.name=vanilla', '+algorithm.tasks.prediction.history_guidance.guidance_scale=4.0']
Traceback (most recent call last):
  File "/lustre06/project/6067608/achint/diffusion-forcing-transformer/dfot/lib/python3.10/site-packages/urllib3/connection.py", line 198, in _new_conn
    sock = connection.create_connection(
  File "/lustre06/project/6067608/achint/diffusion-forcing-transformer/dfot/lib/python3.10/site-packages/urllib3/util/connection.py", line 85, in create_connection
    raise err
  File "/lustre06/project/6067608/achint/diffusion-forcing-transformer/dfot/lib/python3.10/site-packages/urllib3/util/connection.py", line 73, in create_connection
    sock.connect(sa)
OSError: [Errno 101] Network is unreachable

The above exception was the direct cause of the following exception:

Traceback (most recent call last):
  File "/lustre06/project/6067608/achint/diffusion-forcing-transformer/dfot/lib/python3.10/site-packages/urllib3/connectionpool.py", line 787, in urlopen
    response = self._make_request(
  File "/lustre06/project/6067608/achint/diffusion-forcing-transformer/dfot/lib/python3.10/site-packages/urllib3/connectionpool.py", line 488, in _make_request
    raise new_e
  File "/lustre06/project/6067608/achint/diffusion-forcing-transformer/dfot/lib/python3.10/site-packages/urllib3/connectionpool.py", line 464, in _make_request
    self._validate_conn(conn)
  File "/lustre06/project/6067608/achint/diffusion-forcing-transformer/dfot/lib/python3.10/site-packages/urllib3/connectionpool.py", line 1093, in _validate_conn
    conn.connect()
  File "/lustre06/project/6067608/achint/diffusion-forcing-transformer/dfot/lib/python3.10/site-packages/urllib3/connection.py", line 704, in connect
    self.sock = sock = self._new_conn()
  File "/lustre06/project/6067608/achint/diffusion-forcing-transformer/dfot/lib/python3.10/site-packages/urllib3/connection.py", line 213, in _new_conn
    raise NewConnectionError(
urllib3.exceptions.NewConnectionError: <urllib3.connection.HTTPSConnection object at 0x15219fbb87c0>: Failed to establish a new connection: [Errno 101] Network is unreachable

The above exception was the direct cause of the following exception:

Traceback (most recent call last):
  File "/lustre06/project/6067608/achint/diffusion-forcing-transformer/dfot/lib/python3.10/site-packages/requests/adapters.py", line 667, in send
    resp = conn.urlopen(
  File "/lustre06/project/6067608/achint/diffusion-forcing-transformer/dfot/lib/python3.10/site-packages/urllib3/connectionpool.py", line 841, in urlopen
    retries = retries.increment(
  File "/lustre06/project/6067608/achint/diffusion-forcing-transformer/dfot/lib/python3.10/site-packages/urllib3/util/retry.py", line 519, in increment
    raise MaxRetryError(_pool, url, reason) from reason  # type: ignore[arg-type]
urllib3.exceptions.MaxRetryError: HTTPSConnectionPool(host='huggingface.co', port=443): Max retries exceeded with url: /kiwhansong/DFoT/resolve/main/config.json (Caused by NewConnectionError('<urllib3.connection.HTTPSConnection object at 0x15219fbb87c0>: Failed to establish a new connection: [Errno 101] Network is unreachable'))

During handling of the above exception, another exception occurred:

Traceback (most recent call last):
  File "/lustre06/project/6067608/achint/diffusion-forcing-transformer/dfot/lib/python3.10/site-packages/huggingface_hub/file_download.py", line 1374, in _get_metadata_or_catch_error
    metadata = get_hf_file_metadata(
  File "/lustre06/project/6067608/achint/diffusion-forcing-transformer/dfot/lib/python3.10/site-packages/huggingface_hub/utils/_validators.py", line 114, in _inner_fn
    return fn(*args, **kwargs)
  File "/lustre06/project/6067608/achint/diffusion-forcing-transformer/dfot/lib/python3.10/site-packages/huggingface_hub/file_download.py", line 1294, in get_hf_file_metadata
    r = _request_wrapper(
  File "/lustre06/project/6067608/achint/diffusion-forcing-transformer/dfot/lib/python3.10/site-packages/huggingface_hub/file_download.py", line 278, in _request_wrapper
    response = _request_wrapper(
  File "/lustre06/project/6067608/achint/diffusion-forcing-transformer/dfot/lib/python3.10/site-packages/huggingface_hub/file_download.py", line 301, in _request_wrapper
    response = get_session().request(method=method, url=url, **params)
  File "/lustre06/project/6067608/achint/diffusion-forcing-transformer/dfot/lib/python3.10/site-packages/requests/sessions.py", line 589, in request
    resp = self.send(prep, **send_kwargs)
  File "/lustre06/project/6067608/achint/diffusion-forcing-transformer/dfot/lib/python3.10/site-packages/requests/sessions.py", line 703, in send
    r = adapter.send(request, **kwargs)
  File "/lustre06/project/6067608/achint/diffusion-forcing-transformer/dfot/lib/python3.10/site-packages/huggingface_hub/utils/_http.py", line 93, in send
    return super().send(request, *args, **kwargs)
  File "/lustre06/project/6067608/achint/diffusion-forcing-transformer/dfot/lib/python3.10/site-packages/requests/adapters.py", line 700, in send
    raise ConnectionError(e, request=request)
requests.exceptions.ConnectionError: (MaxRetryError("HTTPSConnectionPool(host='huggingface.co', port=443): Max retries exceeded with url: /kiwhansong/DFoT/resolve/main/config.json (Caused by NewConnectionError('<urllib3.connection.HTTPSConnection object at 0x15219fbb87c0>: Failed to establish a new connection: [Errno 101] Network is unreachable'))"), '(Request ID: d7f6391a-dceb-4cae-86e4-df52f49bb89f)')

The above exception was the direct cause of the following exception:

Traceback (most recent call last):
  File "/lustre06/project/6067608/achint/diffusion-forcing-transformer/main.py", line 261, in run
    download_pretrained(load)
  File "/lustre06/project/6067608/achint/diffusion-forcing-transformer/utils/ckpt_utils.py", line 119, in download_pretrained
    download_from_hf(filename="config.json")
  File "/lustre06/project/6067608/achint/diffusion-forcing-transformer/utils/huggingface_utils.py", line 11, in download_from_hf
    return hf_hub_download(
  File "/lustre06/project/6067608/achint/diffusion-forcing-transformer/dfot/lib/python3.10/site-packages/huggingface_hub/utils/_validators.py", line 114, in _inner_fn
    return fn(*args, **kwargs)
  File "/lustre06/project/6067608/achint/diffusion-forcing-transformer/dfot/lib/python3.10/site-packages/huggingface_hub/file_download.py", line 860, in hf_hub_download
    return _hf_hub_download_to_cache_dir(
  File "/lustre06/project/6067608/achint/diffusion-forcing-transformer/dfot/lib/python3.10/site-packages/huggingface_hub/file_download.py", line 967, in _hf_hub_download_to_cache_dir
    _raise_on_head_call_error(head_call_error, force_download, local_files_only)
  File "/lustre06/project/6067608/achint/diffusion-forcing-transformer/dfot/lib/python3.10/site-packages/huggingface_hub/file_download.py", line 1485, in _raise_on_head_call_error
    raise LocalEntryNotFoundError(
huggingface_hub.errors.LocalEntryNotFoundError: An error happened while trying to locate the file on the Hub and we cannot find the requested files in the local cache. Please check your connection and try again or make sure your Internet connection is on.

Set the environment variable HYDRA_FULL_ERROR=1 for a complete stack trace.
